<?xml version="1.0" encoding="UTF-8"?>
<robot generator="Robot 7.3.1 (Python 3.12.7 on win32)" generated="2025-07-24T21:00:59.931586" rpa="false" schemaversion="5">
<suite id="s1" name="Testcases" source="C:\Users\prati\OneDrive\Desktop\SkillSync-Test\testcases.robot">
<test id="s1-t1" name="Login with ${username}" line="7">
<status status="FAIL" start="2025-07-24T21:01:01.254137" elapsed="0.000000">Test cannot be empty.</status>
</test>
<status status="FAIL" start="2025-07-24T21:00:59.932599" elapsed="1.321538"/>
</suite>
<statistics>
<total>
<stat pass="0" fail="1" skip="0">All Tests</stat>
</total>
<tag>
</tag>
<suite>
<stat name="Testcases" id="s1" pass="0" fail="1" skip="0">Testcases</stat>
</suite>
</statistics>
<errors>
<msg time="2025-07-24T21:01:01.251630" level="ERROR">[ DataDriver ] Error in robot file:
  File "C:\Users\prati\OneDrive\Desktop\SkillSync-Test\testcases.robot", line 0</msg>
<msg time="2025-07-24T21:01:01.252636" level="ERROR">In source file:
  File "SkillSync_Test_Cases.xlsx", line 0</msg>
<msg time="2025-07-24T21:01:01.254137" level="ERROR">Calling method '_start_suite' of listener 'DataDriver' failed: ValueError: Unassigned requiered argument detected: ${username}.</msg>
</errors>
</robot>
